Workbook

Sheet Produtos
A1: id | B1: nome | C1: categoria | D1: subcategoria | E1: marca | F1: embalagem | G1: unidadeVenda | H1: preco | I1: caixaQuantidade | J1: caixaPreco | K1: foto | L1: disponivel | M1: destaque | N1: descricao | O1: publicar | P1: codigoSistema | Q1: ean | R1: status | S1: observacao | T1: estoqueSistema | U1: precoRevenda
A2: polpa-de-acerola-brasfrut-pacote-com-12-100-g | B2: Polpa de Acerola | C2: polpas | D2: Polpa 100 g | E2: Brasfrut | F2: Pacote com 12 × 100 g | G2: pacote | H2: 30 | L2: =TRUE() -> TRUE | M2: =FALSE() -> FALSE | O2: =TRUE() -> TRUE | P2: 50003 | Q2: 7896014400287 | R2: Ok | T2: 154 | U2: 38
A3: polpa-de-cacau-brasfrut-pacote-com-12-100-g | B3: Polpa de Cacau | C3: polpas | D3: Polpa 100 g | E3: Brasfrut | F3: Pacote com 12 × 100 g | G3: pacote | H3: 30 | L3: =TRUE() -> TRUE | M3: =FALSE() -> FALSE | O3: =TRUE() -> TRUE | P3: 50004 | Q3: 7896014400379 | R3: Ok | T3: 19 | U3: 38
A4: polpa-de-caja-brasfrut-pacote-com-12-100-g | B4: Polpa de Cajá | C4: polpas | D4: Polpa 100 g | E4: Brasfrut | F4: Pacote com 12 × 100 g | G4: pacote | H4: 40 | L4: =TRUE() -> TRUE | M4: =FALSE() -> FALSE | O4: =TRUE() -> TRUE | P4: 50005 | Q4: 7896014400461 | R4: Ok | T4: 128 | U4: 50
A5: polpa-de-caju-brasfrut-pacote-com-12-100-g | B5: Polpa de Caju | C5: polpas | D5: Polpa 100 g | E5: Brasfrut | F5: Pacote com 12 × 100 g | G5: pacote | H5: 30 | L5: =TRUE() -> TRUE | M5: =FALSE() -> FALSE | O5: =TRUE() -> TRUE | P5: 50006 | Q5: 7896014400553 | R5: Ok | T5: 87 | U5: 38
A6: polpa-de-cupuacu-brasfrut-pacote-com-12-100-g | B6: Polpa de Cupuaçu | C6: polpas | D6: Polpa 100 g | E6: Brasfrut | F6: Pacote com 12 × 100 g | G6: pacote | H6: 35 | L6: =TRUE() -> TRUE | M6: =FALSE() -> FALSE | O6: =TRUE() -> TRUE | P6: 50007 | Q6: 7896014499007 | R6: Ok | T6: 47
A7: polpa-de-goiaba-brasfrut-pacote-com-12-100-g | B7: Polpa de Goiaba | C7: polpas | D7: Polpa 100 g | E7: Brasfrut | F7: Pacote com 12 × 100 g | G7: pacote | H7: 30 | L7: =TRUE() -> TRUE | M7: =FALSE() -> FALSE | O7: =TRUE() -> TRUE | P7: 50008 | Q7: 7896014400645 | R7: Ok | T7: 22 | U7: 38
A8: polpa-de-graviola-brasfrut-pacote-com-12-100-g | B8: Polpa de Graviola | C8: polpas | D8: Polpa 100 g | E8: Brasfrut | F8: Pacote com 12 × 100 g | G8: pacote | H8: 40 | L8: =TRUE() -> TRUE | M8: =FALSE() -> FALSE | O8: =TRUE() -> TRUE | P8: 50009 | Q8: 7896014401079 | R8: Ok | T8: 21 | U8: 50
A9: polpa-de-manga-brasfrut-pacote-com-12-100-g | B9: Polpa de Manga | C9: polpas | D9: Polpa 100 g | E9: Brasfrut | F9: Pacote com 12 × 100 g | G9: pacote | H9: 30 | L9: =TRUE() -> TRUE | M9: =FALSE() -> FALSE | O9: =TRUE() -> TRUE | P9: 50011 | Q9: 7896014400737 | R9: Ok | T9: 36 | U9: 38
A10: polpa-de-maracuja-brasfrut-pacote-com-12-100-g | B10: Polpa de Maracujá | C10: polpas | D10: Polpa 100 g | E10: Brasfrut | F10: Pacote com 12 × 100 g | G10: pacote | H10: 60 | L10: =TRUE() -> TRUE | M10: =FALSE() -> FALSE | O10: =TRUE() -> TRUE | P10: 50013 | Q10: 7896014400829 | R10: Ok | T10: 320 | U10: 70
A11: polpa-de-morango-brasfrut-pacote-com-12-100-g | B11: Polpa de Morango | C11: polpas | D11: Polpa 100 g | E11: Brasfrut | F11: Pacote com 12 × 100 g | G11: pacote | H11: 40 | L11: =TRUE() -> TRUE | M11: =FALSE() -> FALSE | O11: =TRUE() -> TRUE | P11: 50015 | Q11: 7896014403103 | R11: Ok | T11: 245 | U11: 50
A12: polpa-de-uva-brasfrut-pacote-com-12-100-g | B12: Polpa de Uva | C12: polpas | D12: Polpa 100 g | E12: Brasfrut | F12: Pacote com 12 × 100 g | G12: pacote | H12: 60 | L12: =TRUE() -> TRUE | M12: =FALSE() -> FALSE | O12: =TRUE() -> TRUE | P12: 50018 | Q12: 7896014403455 | R12: Ok | T12: 64
A13: polpa-de-tamarindo-brasfrut-pacote-com-12-100-g | B13: Polpa de Tamarindo | C13: polpas | D13: Polpa 100 g | E13: Brasfrut | F13: Pacote com 12 × 100 g | G13: pacote | H13: 30 | L13: =TRUE() -> TRUE | M13: =FALSE() -> FALSE | O13: =TRUE() -> TRUE | P13: 50019 | Q13: 7896014490004 | R13: Ok | T13: 142 | U13: 38
A14: polpa-de-abacaxi-brasfrut-pacote-com-12-100-g | B14: Polpa de Abacaxi | C14: polpas | D14: Polpa 100 g | E14: Brasfrut | F14: Pacote com 12 × 100 g | G14: pacote | H14: 30 | L14: =TRUE() -> TRUE | M14: =FALSE() -> FALSE | O14: =TRUE() -> TRUE | P14: 50001 | Q14: 7896014400195 | R14: Ok | T14: 184 | U14: 38
A15: polpa-de-abacaxi-nutricau-pacote-com-12-100-g | B15: Polpa de Abacaxi | C15: polpas | D15: Polpa 100 g | E15: Nutricau | F15: Pacote com 12 × 100 g | G15: pacote | H15: 23 | L15: =TRUE() -> TRUE | M15: =FALSE() -> FALSE | O15: =TRUE() -> TRUE | P15: 003 | R15: Ok | T15: 0
A16: polpa-de-umbu-brasfrut-pacote-com-12-100-g | B16: Polpa de Umbu | C16: polpas | D16: Polpa 100 g | E16: Brasfrut | F16: Pacote com 12 × 100 g | G16: pacote | H16: 45 | L16: =TRUE() -> TRUE | M16: =FALSE() -> FALSE | O16: =TRUE() -> TRUE | P16: 50017 | Q16: 7896014400911 | R16: Ok | T16: 2
A17: polpa-de-abacaxi-brasfrut-pacote-1-02-kg-vendido-por-kg | B17: Polpa de Abacaxi | C17: polpas | D17: Polpa 1,02 kg | E17: Brasfrut | F17: Pacote 1,02 kg (vendido por kg) | G17: kg | H17: 12 | L17: =TRUE() -> TRUE | M17: =FALSE() -> FALSE | O17: =TRUE() -> TRUE | P17: 80001 | Q17: 7896014400652 | R17: Ok | T17: 250
A18: polpa-de-acerola-brasfrut-pacote-1-02-kg-vendido-por-kg | B18: Polpa de Acerola | C18: polpas | D18: Polpa 1,02 kg | E18: Brasfrut | F18: Pacote 1,02 kg (vendido por kg) | G18: kg | H18: 12 | L18: =TRUE() -> TRUE | M18: =FALSE() -> FALSE | O18: =TRUE() -> TRUE | P18: 80003 | Q18: 7896014400676 | R18: Ok | T18: 318
A19: polpa-de-caju-brasfrut-pacote-1-02-kg-vendido-por-kg | B19: Polpa de Caju | C19: polpas | D19: Polpa 1,02 kg | E19: Brasfrut | F19: Pacote 1,02 kg (vendido por kg) | G19: kg | H19: 12 | L19: =TRUE() -> TRUE | M19: =FALSE() -> FALSE | O19: =TRUE() -> TRUE | P19: 80006 | Q19: 7896014400706 | R19: Ok | T19: 287
A20: polpa-de-goiaba-brasfrut-pacote-1-02-kg-vendido-por-kg | B20: Polpa de Goiaba | C20: polpas | D20: Polpa 1,02 kg | E20: Brasfrut | F20: Pacote 1,02 kg (vendido por kg) | G20: kg | H20: 12 | L20: =TRUE() -> TRUE | M20: =FALSE() -> FALSE | O20: =TRUE() -> TRUE | P20: 80008 | Q20: 7896014400720 | R20: Ok | T20: 229
A21: polpa-de-tamarindo-brasfrut-pacote-1-02-kg-vendido-por-kg | B21: Polpa de Tamarindo | C21: polpas | D21: Polpa 1,02 kg | E21: Brasfrut | F21: Pacote 1,02 kg (vendido por kg) | G21: kg | H21: 12 | L21: =TRUE() -> TRUE | M21: =FALSE() -> FALSE | O21: =TRUE() -> TRUE | P21: 80019 | Q21: 7896014400843 | R21: Ok | T21: 339
A22: file-de-mapara-por-kg | B22: Filé de Mapará | C22: peixes | D22: Peixes e frutos do mar | F22: Por kg | G22: kg | H22: 39.9 | L22: =TRUE() -> TRUE | M22: =FALSE() -> FALSE | O22: =TRUE() -> TRUE | P22: 60 | R22: Ok | T22: 0
A23: polpa-de-maracuja-fauzi-pacote-com-10-100-g | B23: Polpa de Maracujá | C23: polpas | D23: Polpa 100 g | E23: Fauzi | F23: Pacote com 10 × 100 g | G23: pacote | H23: 40 | L23: =TRUE() -> TRUE | M23: =FALSE() -> FALSE | O23: =TRUE() -> TRUE | P23: 00200 | R23: Ok | T23: 0
A24: posta-de-piramutaba-por-kg | B24: Posta de Piramutaba | C24: peixes | D24: Peixes e frutos do mar | F24: Por kg | G24: kg | H24: 19 | L24: =TRUE() -> TRUE | M24: =FALSE() -> FALSE | O24: =TRUE() -> TRUE | P24: 035 | R24: Ok | T24: 0
A25: file-de-merluza-por-kg | B25: Filé de Merluza | C25: peixes | D25: Peixes e frutos do mar | F25: Por kg | G25: kg | H25: 34.6 | L25: =TRUE() -> TRUE | M25: =FALSE() -> FALSE | O25: =TRUE() -> TRUE | P25: 33 | R25: Ok | T25: 0
A26: camarao-cinza-eviscerado-sem-colinha-por-kg | B26: Camarão Cinza Eviscerado sem Colinha | C26: peixes | D26: Peixes e frutos do mar | F26: Por kg | G26: kg | H26: 79.9 | L26: =TRUE() -> TRUE | M26: =FALSE() -> FALSE | O26: =TRUE() -> TRUE | P26: 0400 | R26: Ok | T26: 0
A27: posta-de-pintado-por-kg-pacote-500-g | B27: Posta de Pintado | C27: peixes | D27: Peixes e frutos do mar | F27: Por kg (pacote 500 g) | G27: kg | H27: 26.8 | L27: =TRUE() -> TRUE | M27: =FALSE() -> FALSE | O27: =TRUE() -> TRUE | P27: 0000034 | R27: Conferir | S27: Sistema: 'POSTA DE PINTADO 500G' com unidade KG. Conferir se o preço é por kg ou por pacote. | T27: 0
A28: bolinho-de-bacalhau-pacote-500-g | B28: Bolinho de Bacalhau | C28: salgados | D28: Salgados | F28: Pacote 500 g | G28: pacote | H28: 20 | L28: =TRUE() -> TRUE | M28: =FALSE() -> FALSE | O28: =TRUE() -> TRUE | P28: 50039 | R28: Ok | T28: 0
A29: polpa-de-tangerina-brasfrut-pacote-com-12-100-g | B29: Polpa de Tangerina | C29: polpas | D29: Polpa 100 g | E29: Brasfrut | F29: Pacote com 12 × 100 g | G29: pacote | H29: 60 | L29: =TRUE() -> TRUE | M29: =FALSE() -> FALSE | O29: =TRUE() -> TRUE | P29: 50021 | Q29: 7896014401567 | R29: Ok | T29: 37
A30: bacalhau-desfiado-por-kg | B30: Bacalhau Desfiado | C30: peixes | D30: Peixes e frutos do mar | F30: Por kg | G30: kg | H30: 65 | L30: =TRUE() -> TRUE | M30: =FALSE() -> FALSE | O30: =TRUE() -> TRUE | P30: 151 | R30: Ok | T30: 0.4
A31: casquinha-de-siri-fast-fish-pacote-300-g | B31: Casquinha de Siri | C31: salgados | D31: Salgados | E31: Fast Fish | F31: Pacote 300 g | G31: pacote | H31: 28 | L31: =TRUE() -> TRUE | M31: =FALSE() -> FALSE | O31: =TRUE() -> TRUE | P31: 51318 | R31: Ok | T31: 0
A32: camarao-sete-barbas-por-kg | B32: Camarão Sete Barbas | C32: peixes | D32: Peixes e frutos do mar | F32: Por kg | G32: kg | H32: 54.9 | L32: =TRUE() -> TRUE | M32: =FALSE() -> FALSE | O32: =TRUE() -> TRUE | P32: 10116 | R32: Ok | T32: 0
A33: file-de-tilapia-por-kg | B33: Filé de Tilápia | C33: peixes | D33: Peixes e frutos do mar | F33: Por kg | G33: kg | H33: 49.9 | L33: =TRUE() -> TRUE | M33: =FALSE() -> FALSE | O33: =TRUE() -> TRUE | P33: 20017 | R33: Ok | T33: 0
A34: file-de-pintado-por-kg-pacote-500-g | B34: Filé de Pintado | C34: peixes | D34: Peixes e frutos do mar | F34: Por kg (pacote 500 g) | G34: kg | H34: 27.3 | L34: =TRUE() -> TRUE | M34: =FALSE() -> FALSE | O34: =TRUE() -> TRUE | P34: 527 | R34: Ok | T34: 0
A35: file-de-salmao-premium-por-kg | B35: Filé de Salmão Premium | C35: peixes | D35: Peixes e frutos do mar | F35: Por kg | G35: kg | H35: 96.9 | L35: =TRUE() -> TRUE | M35: =FALSE() -> FALSE | O35: =TRUE() -> TRUE | P35: 530 | R35: Ok | T35: 0
A36: kani-kama-pacote-250-g | B36: Kani Kama | C36: peixes | D36: Peixes e frutos do mar | F36: Pacote 250 g | G36: pacote | H36: 24 | L36: =TRUE() -> TRUE | M36: =FALSE() -> FALSE | O36: =TRUE() -> TRUE | P36: 250 | R36: Ok | T36: 0
A37: file-de-aruana-por-kg | B37: Filé de Aruanã | C37: peixes | D37: Peixes e frutos do mar | F37: Por kg | G37: kg | H37: 23 | L37: =TRUE() -> TRUE | M37: =FALSE() -> FALSE | O37: =TRUE() -> TRUE | P37: 87 | R37: Ok | T37: 0
A38: camarao-rosa-por-kg | B38: Camarão Rosa | C38: peixes | D38: Peixes e frutos do mar | F38: Por kg | G38: kg | H38: 139.9 | L38: =TRUE() -> TRUE | M38: =FALSE() -> FALSE | O38: =TRUE() -> TRUE | P38: 89 | R38: Ok | T38: 0
A39: file-de-robalo-por-kg | B39: Filé de Robalo | C39: peixes | D39: Peixes e frutos do mar | F39: Por kg | G39: kg | H39: 98 | L39: =TRUE() -> TRUE | M39: =FALSE() -> FALSE | O39: =TRUE() -> TRUE | P39: 25 | R39: Ok | T39: 0
A40: posta-de-pintado-por-kg-pacote-700-g | B40: Posta de Pintado | C40: peixes | D40: Peixes e frutos do mar | F40: Por kg (pacote 700 g) | G40: kg | H40: 54 | L40: =TRUE() -> TRUE | M40: =FALSE() -> FALSE | O40: =TRUE() -> TRUE | P40: 526 | R40: Conferir | S40: Sistema: 'PCT 700G' com unidade KG. Conferir se o preço é por kg ou por pacote. | T40: 0
...

Sheet Catálogo fornecedores
A1: Itens dos catálogos dos fornecedores que NÃO estão na lista do sistema (ou estão com outro nome). Não vão para o site.
A2: Para vender algum deles, copie a linha para a aba Produtos, preencha preço e unidadeVenda e gere o id. Vários peixes daqui podem ser os mesmos do sistema com nome parecido.
A4: nome | B4: categoria | C4: subcategoria | D4: marca | E4: embalagem | F4: ean | G4: código do fornecedor
A5: Polpa de Cacau | B5: polpas | C5: Polpa 1,02 kg | D5: Brasfrut | E5: 1,02 kg | F5: 7896014400683
A6: Polpa de Cajá | B6: polpas | C6: Polpa 1,02 kg | D6: Brasfrut | E6: 1,02 kg | F6: 7896014400690
A7: Polpa de Tangerina | B7: polpas | C7: Polpa 1,02 kg | D7: Brasfrut | E7: 1,02 kg | F7: 7896014400850
A8: Polpa de Umbu | B8: polpas | C8: Polpa 1,02 kg | D8: Brasfrut | E8: 1,02 kg | F8: 7896014400867
A9: Néctar de Abacaxi | B9: polpas | C9: Néctar 200 ml | D9: Brasfrut | E9: 200 ml | F9: 7896014403202
A10: Néctar de Acerola | B10: polpas | C10: Néctar 200 ml | D10: Brasfrut | E10: 200 ml | F10: 7896014403165
A11: Néctar de Caju | B11: polpas | C11: Néctar 200 ml | D11: Brasfrut | E11: 200 ml | F11: 7896014403110
A12: Néctar de Goiaba | B12: polpas | C12: Néctar 200 ml | D12: Brasfrut | E12: 200 ml | F12: 7896014403219
A13: Néctar de Manga | B13: polpas | C13: Néctar 200 ml | D13: Brasfrut | E13: 200 ml | F13: 7896014403127
A14: Néctar de Umbu | B14: polpas | C14: Néctar 200 ml | D14: Brasfrut | E14: 200 ml | F14: 7896014403141
A15: Néctar de Uva | B15: polpas | C15: Néctar 200 ml | D15: Brasfrut | E15: 200 ml | F15: 7896014403226
A16: Néctar de Tangerina | B16: polpas | C16: Néctar 200 ml | D16: Brasfrut | E16: 200 ml | F16: 7896014403189
... A18: Néctar de Misto de Maracujá e Maçã | B18: polpas | C18: Néctar 200 ml | D18: Brasfrut | E18: 200 ml | F18: 7896014403240
A19: Morango Congelado | B19: frutas | C19: Frutas congeladas | D19: Frut Polpas | E19: 1,02 kg
A20: Morango Congelado | B20: frutas | C20: Frutas congeladas | D20: Frut Polpas | E20: 100 g
A21: Amorango Congelado (morango e amora) | B21: frutas | C21: Frutas congeladas | D21: Frut Polpas | E21: 1,02 kg
A22: Frutas Vermelhas Congeladas | B22: frutas | C22: Frutas congeladas | D22: Frut Polpas | E22: 1,02 kg
A23: Amoras Congeladas | B23: frutas | C23: Frutas congeladas | D23: Frut Polpas | E23: 1,02 kg
A24: Polpa de Maracujá com Semente | B24: frutas | C24: Frutas congeladas | D24: Frut Polpas | E24: 1,02 kg
A25: Açaí & Frutas Vermelhas | B25: acai-cremes | C25: Açaí | D25: Frut Polpas | E25: 1,02 L
A26: Açaí Tradicional (com guaraná) | B26: acai-cremes | C26: Açaí | D26: Frut Polpas | E26: 1,02 L
A27: Açaí & Maracujá | B27: acai-cremes | C27: Açaí | D27: Frut Polpas | E27: 1,02 L
A28: Açaí & Leitíssimo Crocante | B28: acai-cremes | C28: Açaí | D28: Frut Polpas | E28: 1,02 L
A29: Açaí Tradicional 5 L | B29: acai-cremes | C29: Açaí | D29: Frut Polpas | E29: 5 L
A30: Creme de Manga | B30: acai-cremes | C30: Cremes Frut Polpas | D30: Frut Polpas | E30: 1,02 kg (1,3 L)
... A48: Gelo Saborizado Amore | B48: gelo | C48: Linha especial | D48: Coco Leve | E48: 55 g
A49: Brownie Bites Chocolate Branco | B49: sobremesas | C49: Sobremesas | D49: Kaffinée | E49: 100 g | G49: 219
A50: Brownie Bites Chocolate ao Leite | B50: sobremesas | C50: Sobremesas | D50: Kaffinée | E50: 100 g | G50: 217
A51: Torta Duo Chocolate | B51: sobremesas | C51: Sobremesas | D51: Kaffinée | E51: 200 g (2 un. de 100 g) | G51: 404
A52: Torta de Chocolate | B52: sobremesas | C52: Sobremesas | D52: Kaffinée | E52: 200 g (2 un. de 100 g) | G52: 406
A53: Bolinho de Bacalhau | B53: salgados | C53: Salgados | E53: Consultar
A54: Bolinho de Camarão | B54: salgados | C54: Salgados | E54: Consultar
A55: Bolinho de Tilápia com Queijo | B55: salgados | C55: Salgados | E55: Consultar
A56: Kibe de Tilápia com Queijo | B56: salgados | C56: Salgados | E56: Consultar
A57: Isca de Tilápia | B57: salgados | C57: Salgados | E57: Consultar
A58: Bolinho de Mandioca com Carne Seca | B58: salgados | C58: Salgados | E58: Consultar
A59: Bolinho de Cabotiá com Carne Seca | B59: salgados | C59: Salgados | E59: Consultar
...

Sheet Como preencher
A1: Planilha de produtos FrutMar
A2: Base do site. A aba Produtos tem os itens da lista do sistema antigo, com preço. Células com fundo creme são as que você edita; cinza é só referência.
A4: Coluna | B4: O que colocar
A5: id | B5: Já gerado. Minúsculo, sem acento, único. Não mude depois que o site estiver no ar (o carrinho usa o id).
A6: nome | B6: Como o cliente vai ler no site.
A7: categoria | B7: Lista: polpas, frutas, acai-cremes, gelo, sobremesas, salgados, peixes. Néctares e polpas em 'polpas'; camarão e frutos do mar em 'peixes'.
A8: subcategoria | B8: Texto livre para agrupar dentro da categoria.
A9: marca | B9: Marca do fornecedor. Vazio se não tiver.
A10: embalagem | B10: O que o cliente recebe. Ex.: 'Pacote com 12 × 100 g', 'Por kg'.
A11: unidadeVenda | B11: Como o preço é cobrado: un, pacote, kg, caixa ou bandeja. O site mostra 'R$ 30,00 / pacote'.
A12: preco | B12: Preço de venda por unidadeVenda, só o número (12,50). Vazio = 'Consulte o preço'. Veio da coluna 'Preço de Venda' do sistema.
A13: caixaQuantidade / caixaPreco | B13: Opcional: se o produto também vende caixa fechada, quantas unidades e o preço. Vazio = não vende por caixa.
A14: foto | B14: Nome do arquivo em src/assets/produtos/ (ex.: polpa-maracuja.jpg). Vazio = imagem padrão com o símbolo.
A15: disponivel | B15: TRUE = pode pedir. FALSE = mostra 'Em falta'.
... A24: precoRevenda | B24: Preço de revenda do sistema. Só referência, não vai para o site.
A26: Exemplo ilustrativo
A27: nome | B27: Polpa de Maracujá
A28: embalagem | B28: Pacote com 12 × 100 g
A29: unidadeVenda | B29: pacote
A30: preco | B30: 60,00
A31: foto | B31: polpa-maracuja.jpg
A32: publicar | B32: TRUE
B33: Só para mostrar o formato: os preços reais estão na aba Produtos.
A35: Depois de editar
B36: 1) Salve a aba Produtos como CSV UTF-8 com o nome produtos.csv, na raiz do projeto. 2) npm run produtos (valida e gera src/data/produtos.json). 3) Commit e push: o site atualiza sozinho.

Sheet Pendências
A1: Pendências e decisões
A3: 1 | B3: Preço igual para todos? | C3: O sistema tem 'Preço de Venda' e 'Preço de Revenda' (revenda é maior, ex.: polpa R$ 30 x R$ 38). O site usa só o Preço de Venda, porque vocês disseram que o preço é o mesmo para todos. Confirmar com o chefe. O Preço de Revenda ficou na coluna de referência.
A4: 2 | B4: Polpas 100 g: pacote de 12 | C4: No sistema a polpa 100 g é vendida por PACOTE com 12 (ex.: R$ 30,00, ou R$ 2,50 a polpa). O site mostra 'R$ 30,00 / pacote'. Decidir se o consumidor final pode comprar só 1 polpa avulsa, e a que preço. Hoje não existe esse item no sistema.
A5: 3 | B5: Polpas 1,02 kg e frutas: preço por kg | C5: O sistema cobra por KG (ex.: polpa 1,02 kg a R$ 12,00/kg). O site mostra 'R$ 12,00 / kg'. Decidir se o cliente pede em kg ou por pacote inteiro (1,02 kg = R$ 12,24). O pedido pelo site aceita quantidade com meio kg.
A6: 4 | B6: Cremes Brasfrut | C6: Sistema: 'CX 06X1,02KG' a R$ 18,66 a R$ 27,80. O preço parece ser por pote, não por caixa de 6. Conferir. Está marcado 'Conferir'.
A7: 5 | B7: Gelo Coco Leve | C7: Sistema: 190 g, unidade 'CX', R$ 2,60. O catálogo do fornecedor diz 55 g. Conferir peso e se o preço é por unidade.
A8: 6 | B8: Peixes: unidade KG com peso na descrição | C8: Posta de pintado 500 g / 700 g, posta de mapará 700 g e filé de pintado 500 g têm unidade KG. O preço parece por kg, mas alguns valores são baixos (mapará R$ 16,00). Conferir.
A9: 7 | B9: Morango com marca FrutBras | C9: O item 0611 'Morango Fruta FrutBras 1,02 kg' tem o maior estoque do sistema (759). No site aparece só como 'Morango Congelado', sem marca e sem foto da embalagem, junto com Frut Center e AHS. Confirmar com o chefe se mostra os três ou só um.
A10: 8 | B10: Outras marcas de polpa | C10: O sistema tem polpas Nature, Canaã, Nutricau e Fauzi, quase todas com estoque zero. Estão na aba Produtos com publicar = TRUE. Decidir se ficam ou saem do site (publicar = FALSE).
A11: 9 | B11: Estoque | C11: 100 dos 154 itens estão com estoque 0 no sistema (quase todos os peixes e salgados). Pode ser que o estoque desses itens não seja controlado. Decidir a regra do site: mostrar sempre, mostrar 'Em falta' ou esconder (pergunta 7 do PRD). O estoque não entra no site; ele muda todo dia.
A12: 10 | B12: Itens que não são produtos | C12: Ficaram de fora: Frete 8% (1602), Freezer 300 L (20253) e um injetor de veículo (00204).
A13: 11 | B13: Código de barras do sistema | C13: As colunas de EAN do sistema vieram cortadas (10 dígitos, repetidas). Não foram usadas. O EAN completo vem do catálogo Brasfrut.
A14: 12 | B14: Itens do catálogo fora da lista | C14: Brownie Bites, tortas, néctares, cremes de açaí de 3 kg, Açaí Frut Polpas, salgados do catálogo e ~190 peixes do catálogo CenterFish não aparecem (ou aparecem com outro nome) no sistema. Estão na aba 'Catálogo fornecedores' como referência.
... A17: 15 | B17: Categorias | C17: O PRD tem 7 categorias. Néctares (só no catálogo) iriam para 'polpas' e camarão/frutos do mar ficam em 'peixes'.

Sheet Resumo
A1: Resumo por categoria (aba Produtos)
A3: Categoria | B3: Produtos | C3: Com preço | D3: A conferir | E3: Para publicar | F3: Estoque zero
A4: polpas | B4: =COUNTIF(Produtos!$C$2:$C$2000,A4) -> 39 | C4: =COUNTIFS(Produtos!$C$2:$C$2000,A4,Produtos!$H$2:$H$2000,">0") -> 39 | D4: =COUNTIFS(Produtos!$C$2:$C$2000,A4,Produtos!$R$2:$R$2000,"Conferir") -> 1 | E4: =COUNTIFS(Produtos!$C$2:$C$2000,A4,Produtos!$O$2:$O$2000,TRUE()) -> 39 | F4: =COUNTIFS(Produtos!$C$2:$C$2000,A4,Produtos!$T$2:$T$2000,0) -> 10
A5: frutas | B5: =COUNTIF(Produtos!$C$2:$C$2000,A5) -> 9 | C5: =COUNTIFS(Produtos!$C$2:$C$2000,A5,Produtos!$H$2:$H$2000,">0") -> 9 | D5: =COUNTIFS(Produtos!$C$2:$C$2000,A5,Produtos!$R$2:$R$2000,"Conferir") -> 1 | E5: =COUNTIFS(Produtos!$C$2:$C$2000,A5,Produtos!$O$2:$O$2000,TRUE()) -> 9 | F5: =COUNTIFS(Produtos!$C$2:$C$2000,A5,Produtos!$T$2:$T$2000,0) -> 6
A6: acai-cremes | B6: =COUNTIF(Produtos!$C$2:$C$2000,A6) -> 6 | C6: =COUNTIFS(Produtos!$C$2:$C$2000,A6,Produtos!$H$2:$H$2000,">0") -> 6 | D6: =COUNTIFS(Produtos!$C$2:$C$2000,A6,Produtos!$R$2:$R$2000,"Conferir") -> 6 | E6: =COUNTIFS(Produtos!$C$2:$C$2000,A6,Produtos!$O$2:$O$2000,TRUE()) -> 6 | F6: =COUNTIFS(Produtos!$C$2:$C$2000,A6,Produtos!$T$2:$T$2000,0) -> 4
A7: gelo | B7: =COUNTIF(Produtos!$C$2:$C$2000,A7) -> 18 | C7: =COUNTIFS(Produtos!$C$2:$C$2000,A7,Produtos!$H$2:$H$2000,">0") -> 18 | D7: =COUNTIFS(Produtos!$C$2:$C$2000,A7,Produtos!$R$2:$R$2000,"Conferir") -> 18 | E7: =COUNTIFS(Produtos!$C$2:$C$2000,A7,Produtos!$O$2:$O$2000,TRUE()) -> 18 | F7: =COUNTIFS(Produtos!$C$2:$C$2000,A7,Produtos!$T$2:$T$2000,0) -> 1
A8: sobremesas | B8: =COUNTIF(Produtos!$C$2:$C$2000,A8) -> 12 | C8: =COUNTIFS(Produtos!$C$2:$C$2000,A8,Produtos!$H$2:$H$2000,">0") -> 12 | D8: =COUNTIFS(Produtos!$C$2:$C$2000,A8,Produtos!$R$2:$R$2000,"Conferir") -> 0 | E8: =COUNTIFS(Produtos!$C$2:$C$2000,A8,Produtos!$O$2:$O$2000,TRUE()) -> 12 | F8: =COUNTIFS(Produtos!$C$2:$C$2000,A8,Produtos!$T$2:$T$2000,0) -> 10
A9: salgados | B9: =COUNTIF(Produtos!$C$2:$C$2000,A9) -> 22 | C9: =COUNTIFS(Produtos!$C$2:$C$2000,A9,Produtos!$H$2:$H$2000,">0") -> 22 | D9: =COUNTIFS(Produtos!$C$2:$C$2000,A9,Produtos!$R$2:$R$2000,"Conferir") -> 0 | E9: =COUNTIFS(Produtos!$C$2:$C$2000,A9,Produtos!$O$2:$O$2000,TRUE()) -> 22 | F9: =COUNTIFS(Produtos!$C$2:$C$2000,A9,Produtos!$T$2:$T$2000,0) -> 22
A10: peixes | B10: =COUNTIF(Produtos!$C$2:$C$2000,A10) -> 48 | C10: =COUNTIFS(Produtos!$C$2:$C$2000,A10,Produtos!$H$2:$H$2000,">0") -> 48 | D10: =COUNTIFS(Produtos!$C$2:$C$2000,A10,Produtos!$R$2:$R$2000,"Conferir") -> 3 | E10: =COUNTIFS(Produtos!$C$2:$C$2000,A10,Produtos!$O$2:$O$2000,TRUE()) -> 48 | F10: =COUNTIFS(Produtos!$C$2:$C$2000,A10,Produtos!$T$2:$T$2000,0) -> 47
A11: Total | B11: =SUM(B4:B10) -> 154 | C11: =SUM(C4:C10) -> 154 | D11: =SUM(D4:D10) -> 29 | E11: =SUM(E4:E10) -> 154 | F11: =SUM(F4:F10) -> 100
